internal/orderbook/testdata/output.txt
# Scenario 1
A, 1, 1
B, B, 10, 100
A, 1, 2
B, S, 12, 100
A, 2, 101
A, 2, 102
B, S, 11, 100
R, 1, 3
R, 2, 103
A, 1, 4
B, B, 10, 200
A, 2, 104
B, S, 11, 200

# Scenario 2
A, 1, 1
B, B, 10, 100
A, 1, 2
B, S, 12, 100
A, 2, 102
B, S, 11, 100
R, 2, 103
A, 1, 3
B, B, 10, 200

# Scenario 3
A, 1, 1
B, B, 10, 100
A, 2, 101
A, 2, 102
B, S, 11, 100
R, 1, 2
A, 2, 103
B, S, 11, 200

# Scenario 4
A, 1, 1
B, B, 10, 100
A, 1, 2
B, S, 12, 100
A, 2, 101
A, 2, 102
B, S, 11, 100
R, 2, 103

# Scenario 5
A, 1, 1
B, B, 10, 100
A, 1, 2
B, S, 12, 100
A, 2, 101
A, 2, 102
B, S, 11, 100
R, 1, 103

# Scenario 6
A, 1, 1
B, B, 10, 100
A, 1, 2
B, S, 16, 100
A, 2, 101
A, 2, 102
B, S, 15, 100
A, 2, 103
B, B, 11, 100
A, 1, 3
B, S, 14, 100

# Scenario 7
A, 1, 1
B, B, 10, 100
A, 1, 2
B, S, 12, 100
A, 2, 101
A, 2, 102
B, S, 11, 100
R, 2, 103

# Scenario 8
A, 1, 1
B, B, 10, 100
A, 1, 2
B, S, 12, 100
A, 2, 101
A, 2, 102
B, S, 11, 100
R, 1, 3

# Scenario 9
A, 1, 1
B, B, 10, 100
A, 1, 2
B, S, 12, 100
A, 2, 101
A, 2, 102
B, S, 11, 100
A, 1, 1
B, B, 9, 100
A, 2, 102
B, S, 12, 100

# Scenario 10
A, 1, 1
B, B, 10, 100
A, 1, 2
B, S, 12, 100
A, 2, 101
A, 2, 102
B, S, 11, 100
A, 1, 2
A, 2, 101

# Scenario 11
A, 1, 1
B, B, 10, 100
A, 1, 2
B, S, 12, 100
A, 2, 101
A, 2, 102
B, S, 11, 100
A, 1, 1
B, B, 9, 100
A, 2, 101
B, B, -, -

# Scenario 12
A, 1, 1
B, B, 10, 100
A, 1, 2
B, S, 12, 100
A, 2, 101
A, 2, 102
B, S, 11, 100
A, 2, 103
B, S, 11, 200
A, 2, 103
B, S, 11, 100
A, 2, 102
B, S, 12, 100
A, 1, 2
B, S, -, -

# Scenario 13 (Scenario 5 With Trade)
A, 1, 1
B, B, 10, 100
A, 1, 2
B, S, 12, 100
A, 2, 101
A, 2, 102
B, S, 11, 100
A, 1, 103
T, 1, 103, 2, 102, 11, 100
B, S, 12, 100

# Scenario 14 (Scenario 3 With Trade)
A, 1, 1
B, B, 10, 100
A, 2, 101
A, 2, 102
B, S, 11, 100
A, 1, 2
T, 1, 2, 2, 102, 11, 100
B, S, -, -
A, 2, 103
B, S, 11, 100

# Scenario 15: Partial trade
A, 1, 1
B, B, 10, 100
A, 1, 2
B, S, 12, 100
A, 2, 101
A, 2, 102
B, S, 11, 100
A, 1, 103
T, 1, 103, 2, 102, 11, 50
B, S, 11, 50

# Scenario 16: Trade + Partial Trade
A, 1, 1
B, B, 10, 100
A, 1, 2
B, S, 12, 100
A, 2, 101
A, 2, 102
B, S, 11, 100
A, 3, 103
T, 3, 103, 2, 102, 11, 100
T, 3, 103, 1, 2, 12, 50
B, S, 12, 50
